[2022-05-16 10:10:01,652] {taskinstance.py:896} INFO - Dependencies all met for <TaskInstance: a6.schedule_bgg_crawler 2022-05-16T10:05:00+00:00 [queued]>
[2022-05-16 10:10:01,656] {taskinstance.py:896} INFO - Dependencies all met for <TaskInstance: a6.schedule_bgg_crawler 2022-05-16T10:05:00+00:00 [queued]>
[2022-05-16 10:10:01,656] {taskinstance.py:1087} INFO - 
--------------------------------------------------------------------------------
[2022-05-16 10:10:01,656] {taskinstance.py:1088} INFO - Starting attempt 1 of 1
[2022-05-16 10:10:01,656] {taskinstance.py:1089} INFO - 
--------------------------------------------------------------------------------
[2022-05-16 10:10:01,664] {taskinstance.py:1107} INFO - Executing <Task(BashOperator): schedule_bgg_crawler> on 2022-05-16T10:05:00+00:00
[2022-05-16 10:10:01,668] {standard_task_runner.py:52} INFO - Started process 286 to run task
[2022-05-16 10:10:01,673] {standard_task_runner.py:76} INFO - Running: ['***', 'tasks', 'run', 'a6', 'schedule_bgg_crawler', '2022-05-16T10:05:00+00:00', '--job-id', '55', '--pool', 'default_pool', '--raw', '--subdir', 'DAGS_FOLDER/test/test.py', '--cfg-path', '/tmp/tmp4b36ubw8', '--error-file', '/tmp/tmphaso2lth']
[2022-05-16 10:10:01,673] {standard_task_runner.py:77} INFO - Job 55: Subtask schedule_bgg_crawler
[2022-05-16 10:10:01,720] {logging_mixin.py:104} INFO - Running <TaskInstance: a6.schedule_bgg_crawler 2022-05-16T10:05:00+00:00 [running]> on host 18ce7979051b
[2022-05-16 10:10:01,757] {taskinstance.py:1300} INFO - Exporting the following env vars:
AIRFLOW_CTX_DAG_OWNER=***
AIRFLOW_CTX_DAG_ID=a6
AIRFLOW_CTX_TASK_ID=schedule_bgg_crawler
AIRFLOW_CTX_EXECUTION_DATE=2022-05-16T10:05:00+00:00
AIRFLOW_CTX_DAG_RUN_ID=scheduled__2022-05-16T10:05:00+00:00
[2022-05-16 10:10:01,758] {subprocess.py:52} INFO - Tmp dir root location: 
 /tmp
[2022-05-16 10:10:01,758] {subprocess.py:63} INFO - Running command: ['bash', '-c', 'cd /opt/***/dags/test && scrapy crawl thongbao && echo "xong t1"']
[2022-05-16 10:10:01,762] {subprocess.py:75} INFO - Output:
[2022-05-16 10:10:02,606] {subprocess.py:79} INFO - Traceback (most recent call last):
[2022-05-16 10:10:02,606] {subprocess.py:79} INFO -   File "/home/***/.local/lib/python3.8/site-packages/mysql/connector/connection_cext.py", line 233, in _open_connection
[2022-05-16 10:10:02,606] {subprocess.py:79} INFO -     self._cmysql.connect(**cnx_kwargs)
[2022-05-16 10:10:02,606] {subprocess.py:79} INFO - _mysql_connector.MySQLInterfaceError: Can't connect to MySQL server on '127.0.0.1' (111)
[2022-05-16 10:10:02,606] {subprocess.py:79} INFO - 
[2022-05-16 10:10:02,606] {subprocess.py:79} INFO - During handling of the above exception, another exception occurred:
[2022-05-16 10:10:02,606] {subprocess.py:79} INFO - 
[2022-05-16 10:10:02,606] {subprocess.py:79} INFO - Traceback (most recent call last):
[2022-05-16 10:10:02,606] {subprocess.py:79} INFO -   File "/home/***/.local/bin/scrapy", line 8, in <module>
[2022-05-16 10:10:02,606] {subprocess.py:79} INFO -     sys.exit(execute())
[2022-05-16 10:10:02,606] {subprocess.py:79} INFO -   File "/home/***/.local/lib/python3.8/site-packages/scrapy/cmdline.py", line 144, in execute
[2022-05-16 10:10:02,606] {subprocess.py:79} INFO -     cmd.crawler_process = CrawlerProcess(settings)
[2022-05-16 10:10:02,606] {subprocess.py:79} INFO -   File "/home/***/.local/lib/python3.8/site-packages/scrapy/crawler.py", line 290, in __init__
[2022-05-16 10:10:02,606] {subprocess.py:79} INFO -     super().__init__(settings)
[2022-05-16 10:10:02,606] {subprocess.py:79} INFO -   File "/home/***/.local/lib/python3.8/site-packages/scrapy/crawler.py", line 167, in __init__
[2022-05-16 10:10:02,606] {subprocess.py:79} INFO -     self.spider_loader = self._get_spider_loader(settings)
[2022-05-16 10:10:02,606] {subprocess.py:79} INFO -   File "/home/***/.local/lib/python3.8/site-packages/scrapy/crawler.py", line 161, in _get_spider_loader
[2022-05-16 10:10:02,606] {subprocess.py:79} INFO -     return loader_cls.from_settings(settings.frozencopy())
[2022-05-16 10:10:02,607] {subprocess.py:79} INFO -   File "/home/***/.local/lib/python3.8/site-packages/scrapy/spiderloader.py", line 67, in from_settings
[2022-05-16 10:10:02,607] {subprocess.py:79} INFO -     return cls(settings)
[2022-05-16 10:10:02,607] {subprocess.py:79} INFO -   File "/home/***/.local/lib/python3.8/site-packages/scrapy/spiderloader.py", line 24, in __init__
[2022-05-16 10:10:02,607] {subprocess.py:79} INFO -     self._load_all_spiders()
[2022-05-16 10:10:02,607] {subprocess.py:79} INFO -   File "/home/***/.local/lib/python3.8/site-packages/scrapy/spiderloader.py", line 51, in _load_all_spiders
[2022-05-16 10:10:02,607] {subprocess.py:79} INFO -     for module in walk_modules(name):
[2022-05-16 10:10:02,607] {subprocess.py:79} INFO -   File "/home/***/.local/lib/python3.8/site-packages/scrapy/utils/misc.py", line 80, in walk_modules
[2022-05-16 10:10:02,607] {subprocess.py:79} INFO -     mod = import_module(path)
[2022-05-16 10:10:02,607] {subprocess.py:79} INFO -   File "/usr/local/lib/python3.8/importlib/__init__.py", line 127, in import_module
[2022-05-16 10:10:02,607] {subprocess.py:79} INFO -     return _bootstrap._gcd_import(name[level:], package, level)
[2022-05-16 10:10:02,607] {subprocess.py:79} INFO -   File "<frozen importlib._bootstrap>", line 1014, in _gcd_import
[2022-05-16 10:10:02,607] {subprocess.py:79} INFO -   File "<frozen importlib._bootstrap>", line 991, in _find_and_load
[2022-05-16 10:10:02,607] {subprocess.py:79} INFO -   File "<frozen importlib._bootstrap>", line 975, in _find_and_load_unlocked
[2022-05-16 10:10:02,607] {subprocess.py:79} INFO -   File "<frozen importlib._bootstrap>", line 671, in _load_unlocked
[2022-05-16 10:10:02,607] {subprocess.py:79} INFO -   File "<frozen importlib._bootstrap_external>", line 843, in exec_module
[2022-05-16 10:10:02,607] {subprocess.py:79} INFO -   File "<frozen importlib._bootstrap>", line 219, in _call_with_frames_removed
[2022-05-16 10:10:02,607] {subprocess.py:79} INFO -   File "/opt/***/dags/test/thongbao/spiders/__init__.py", line 3, in <module>
[2022-05-16 10:10:02,607] {subprocess.py:79} INFO -     from getAndCheckDB import *
[2022-05-16 10:10:02,607] {subprocess.py:79} INFO -   File "/opt/***/dags/test/getAndCheckDB.py", line 22, in <module>
[2022-05-16 10:10:02,607] {subprocess.py:79} INFO -     mydb = mysql.connector.connect(
[2022-05-16 10:10:02,608] {subprocess.py:79} INFO -   File "/home/***/.local/lib/python3.8/site-packages/mysql/connector/__init__.py", line 270, in connect
[2022-05-16 10:10:02,608] {subprocess.py:79} INFO -     return CMySQLConnection(*args, **kwargs)
[2022-05-16 10:10:02,608] {subprocess.py:79} INFO -   File "/home/***/.local/lib/python3.8/site-packages/mysql/connector/connection_cext.py", line 86, in __init__
[2022-05-16 10:10:02,608] {subprocess.py:79} INFO -     self.connect(**kwargs)
[2022-05-16 10:10:02,608] {subprocess.py:79} INFO -   File "/home/***/.local/lib/python3.8/site-packages/mysql/connector/abstracts.py", line 985, in connect
[2022-05-16 10:10:02,608] {subprocess.py:79} INFO -     self._open_connection()
[2022-05-16 10:10:02,608] {subprocess.py:79} INFO -   File "/home/***/.local/lib/python3.8/site-packages/mysql/connector/connection_cext.py", line 235, in _open_connection
[2022-05-16 10:10:02,608] {subprocess.py:79} INFO -     raise errors.get_mysql_exception(msg=exc.msg, errno=exc.errno,
[2022-05-16 10:10:02,608] {subprocess.py:79} INFO - mysql.connector.errors.DatabaseError: 2003 (HY000): Can't connect to MySQL server on '127.0.0.1' (111)
[2022-05-16 10:10:02,654] {subprocess.py:83} INFO - Command exited with return code 1
[2022-05-16 10:10:02,660] {taskinstance.py:1501} ERROR - Task failed with exception
Traceback (most recent call last):
  File "/home/airflow/.local/lib/python3.8/site-packages/airflow/models/taskinstance.py", line 1157, in _run_raw_task
    self._prepare_and_execute_task_with_callbacks(context, task)
  File "/home/airflow/.local/lib/python3.8/site-packages/airflow/models/taskinstance.py", line 1331, in _prepare_and_execute_task_with_callbacks
    result = self._execute_task(context, task_copy)
  File "/home/airflow/.local/lib/python3.8/site-packages/airflow/models/taskinstance.py", line 1361, in _execute_task
    result = task_copy.execute(context=context)
  File "/home/airflow/.local/lib/python3.8/site-packages/airflow/operators/bash.py", line 180, in execute
    raise AirflowException('Bash command failed. The command returned a non-zero exit code.')
airflow.exceptions.AirflowException: Bash command failed. The command returned a non-zero exit code.
[2022-05-16 10:10:02,661] {taskinstance.py:1544} INFO - Marking task as FAILED. dag_id=a6, task_id=schedule_bgg_crawler, execution_date=20220516T100500, start_date=20220516T101001, end_date=20220516T101002
[2022-05-16 10:10:02,685] {local_task_job.py:151} INFO - Task exited with return code 1
